#VRML_SIM R2023b utf8

EXTERNPROTO "https://raw.githubusercontent.com/cyberbotics/webots/R2023b/projects/objects/backgrounds/protos/TexturedBackground.proto"
EXTERNPROTO "https://raw.githubusercontent.com/cyberbotics/webots/R2023b/projects/objects/backgrounds/protos/TexturedBackgroundLight.proto"
EXTERNPROTO "https://raw.githubusercontent.com/cyberbotics/webots/R2023b/projects/objects/floors/protos/CircleArena.proto"
EXTERNPROTO "https://raw.githubusercontent.com/cyberbotics/webots/R2023b/projects/objects/animals/protos/Cat.proto"
EXTERNPROTO "https://raw.githubusercontent.com/cyberbotics/webots/R2023b/projects/appearances/protos/Cardboard.proto"
EXTERNPROTO "https://raw.githubusercontent.com/cyberbotics/webots/R2023b/projects/appearances/protos/RoughPine.proto"
EXTERNPROTO "https://raw.githubusercontent.com/cyberbotics/webots/R2023b/projects/appearances/protos/MarbleTiles.proto"
EXTERNPROTO "https://raw.githubusercontent.com/cyberbotics/webots/R2023b/projects/appearances/protos/BakelitePlastic.proto"

WorldInfo {
  basicTimeStep 1
  FPS 120
  contactProperties [
    ContactProperties {
      maxContactJoints 16
    }
  ]
}
Viewpoint {
  orientation 0.07328217410695036 0.7326242101912668 -0.676676798478994 0.5212470393875374
  position -2.5523683622882367 0.9308068960541016 1.378389489310476
}
TexturedBackground {
}
TexturedBackgroundLight {
}
CircleArena {
  radius 2
}
Cat {
  translation -0.581056 0.58956 0
  rotation 0 0 1 -2.3561953071795863
}
Robot {
  translation 0 0 0.4
  children [
    Solid {
      translation 0 0.2 0.05
      children [
        Shape {
          appearance BakelitePlastic {
          }
          geometry Sphere {
            radius 0.01
          }
        }
      ]
      name "head"
    }
    Gyro {
      rotation 0 0 1 1.5708003061004252
    }
    InertialUnit {
      rotation 0 0 1 1.5708003061004252
      name "inertial"
    }
    Shape {
      appearance Cardboard {
      }
      geometry DEF BODY Box {
        size 0.28 0.38 0.18
      }
    }
    HingeJoint {
      jointParameters HingeJointParameters {
        anchor -0.165 0 0
        minStop -0.7
        maxStop 0.7
      }
      device [
        PositionSensor {
          name "ps_j1"
        }
        RotationalMotor {
          name "joint_motor_1"
          maxVelocity 30
          minPosition -0.7
          maxPosition 0.7
          maxTorque 20
        }
      ]
      endPoint Solid {
        translation -0.1649999991572505 4.7398320833502705e-07 -0.15000056273260184
        rotation 0.9999987775857904 -0.001197182355614111 -0.0010057739965919144 4.692706653739929e-06
        children [
          HingeJoint {
            jointParameters HingeJointParameters {
              anchor -0.015 0 -0.15
            }
            device [
              PositionSensor {
                name "ps_w1"
              }
              RotationalMotor {
                name "wheel_motor_1"
                maxVelocity 30
                maxTorque 5
              }
            ]
            endPoint Solid {
              translation -0.015 0 -0.15
              rotation 7.850449076788096e-17 1 0 1.5707996938995745
              children [
                Shape {
                  appearance MarbleTiles {
                  }
                  geometry DEF WHEEL Cylinder {
                    height 0.015
                    radius 0.075
                  }
                }
              ]
              name "wheel1"
              boundingObject USE WHEEL
              physics DEF PH_WHEEL Physics {
                density -1
                mass 1
              }
            }
          }
          Shape {
            appearance RoughPine {
            }
            geometry DEF LEG Box {
              size 0.015 0.015 0.3
            }
          }
        ]
        name "leg1"
        boundingObject USE LEG
        physics DEF PH_LEG Physics {
          density -1
          mass 0.5
        }
      }
    }
    HingeJoint {
      jointParameters HingeJointParameters {
        anchor 0.165 0 0
        minStop -0.7
        maxStop 0.7
      }
      device [
        RotationalMotor {
          name "joint_motor_2"
          maxVelocity 30
          minPosition -0.7
          maxPosition 0.7
          maxTorque 20
        }
        PositionSensor {
          name "ps_j2"
        }
      ]
      endPoint Solid {
        translation 0.16499999915455213 4.739832100836283e-07 -0.15000056273259946
        rotation 0.999998764316462 0.0012010989754328758 0.0010142617020788521 4.6928012867022945e-06
        children [
          HingeJoint {
            jointParameters HingeJointParameters {
              anchor 0.015 0 -0.15
            }
            device [
              RotationalMotor {
                name "wheel_motor_2"
                maxVelocity 30
                maxTorque 5
              }
              PositionSensor {
                name "ps_w2"
              }
            ]
            endPoint Solid {
              translation 0.015 0 -0.15
              rotation 1.9626122691970238e-17 1 0 1.5707996938995743
              children [
                Shape {
                  appearance MarbleTiles {
                  }
                  geometry USE WHEEL
                }
              ]
              name "wheel2"
              boundingObject USE WHEEL
              physics USE PH_WHEEL
            }
          }
          Shape {
            appearance RoughPine {
            }
            geometry USE LEG
          }
        ]
        name "leg2"
        boundingObject USE LEG
        physics USE PH_LEG
      }
    }
  ]
  boundingObject USE BODY
  physics Physics {
    density -1
    mass 10
  }
  controller "<extern>"
}
